<sdf version='1.6'>
  <world name='default'>

<include>
<uri>model://sun</uri>
</include>



    <gravity>0 0 -9.8</gravity>
    <magnetic_field>6e-06 2.3e-05 -4.2e-05</magnetic_field>
    <atmosphere type='adiabatic'/>

    <physics name='default_physics' default='0' type='ode'>
      <max_step_size>0.001</max_step_size>
      <real_time_factor>1</real_time_factor>
      <real_time_update_rate>1000</real_time_update_rate>
    </physics>

    <scene>
      <ambient>0.4 0.4 0.4 1</ambient>
      <background>0.7 0.7 0.7 1</background>
      <shadows>1</shadows>
    </scene>

    <audio>
      <device>default</device>
    </audio>

    <spherical_coordinates>
      <surface_model>EARTH_WGS84</surface_model>
      <latitude_deg>0</latitude_deg>
      <longitude_deg>0</longitude_deg>
      <elevation>0</elevation>
      <heading_deg>0</heading_deg>
    </spherical_coordinates>

    <gui fullscreen='0'>
      <camera name='user_camera'>
        <pose frame=''>16.933 -7.39649 7.48163 0 0.371643 2.38418</pose>
        <view_controller>orbit</view_controller>
        <projection_type>perspective</projection_type>
      </camera>
    </gui>



   <model name='ground_plane'>
      <static>1</static>
      <link name='ground_plane::link'>
        <collision name='collision'>
          <geometry>
            <plane>
              <normal>0 0 1</normal>
              <size>100 100</size>
            </plane>
          </geometry>
          <surface>
            <contact>
              <collide_bitmask>65535</collide_bitmask>
              <ode/>
            </contact>
            <friction>
              <ode>
                <mu>100</mu>
                <mu2>50</mu2>
              </ode>
              <torsional>
                <ode/>
              </torsional>
            </friction>
            <bounce/>
          </surface>
          <max_contacts>10</max_contacts>
        </collision>
        <visual name='visual'>
          <cast_shadows>0</cast_shadows>
          <geometry>
            <plane>
              <normal>0 0 1</normal>
              <size>100 100</size>
            </plane>
          </geometry>
          <material>
            <script>
              <uri>file://media/materials/scripts/gazebo.material</uri>
              <name>Gazebo/Grey</name>
            </script>
          </material>
        </visual>
        <self_collide>0</self_collide>
        <enable_wind>0</enable_wind>
        <kinematic>1</kinematic>
      </link>
      <pose frame=''>2.66059 -3.41327 0 0 -0 0</pose>
      <enable_wind>0</enable_wind>
    </model>







    









<model name="myrobot">
      <pose frame="">0 0 0 0 0 0</pose>
      <self_collide>1</self_collide>
      
      <link name="base">
        <pose>0 0 0.1 0 0 0</pose>
        <visual name="baseV">
           <pose>0 0 0 0 0 0</pose>
           <geometry>
             <box>
               <size>0.5 0.7 0.2</size>
             </box>
           </geometry>
        </visual>
        <collision name="baseC">
           <pose>0 0 0 0 0 0</pose>
           <geometry>
	     <box>
               <size>0.5 1 0.2</size>
             </box>
           </geometry>
      </collision>
      <surface>
	<contact>
	  <ode>
	    <soft_cfm>0</soft_cfm>
	    <soft_erp>0.2</soft_erp>
	    <kp>1e+13</kp>
	    <kd>1e+11</kd>
	    <max_vel>-1</max_vel>
	    <max_depth>0</max_depth>
	  </ode>
	</contact>
	<friction>
	   <torcional>
	     <ode>
	     </ode>
	   </torcional>
	</friction>
      </surface>
     </link>

     <link name="eslabon1">
        <pose>0 0 0.7 0 0 0</pose>
        <visual name="eslabon1V">
           <pose>0 0 0 0 0 0</pose>
           <geometry>
             <box>
               <size>0.05 0.05 1</size>
             </box>
           </geometry>
        </visual>
        <collision name="eslabon1C">
           <pose>0 0 0 0 0 0</pose>
           <geometry>
	     <box>
               <size>0.05 0.05 1</size>
             </box>
           </geometry>
           <surface>
	     <contact>
	       <ode>
	          <soft_cfm>0</soft_cfm>
	          <soft_erp>0.2</soft_erp>
	          <kp>1e+13</kp>
	          <kd>1e+11</kd>
	          <max_vel>-1</max_vel>
	          <max_depth>0</max_depth>
	        </ode>
	     </contact>
            <friction>
              <torcional>
	        <ode>
	        </ode>
              </torcional>
            </friction>
          </surface>
      </collision>
     </link>

     <link name="eslabon2">
        <pose>-0.05 0 1.65 0 0 0</pose>
        <visual name="eslabon2V">
           <pose>0 0 0 0 0 0</pose>
           <geometry>
             <box>
               <size>0.05 0.05 1</size>
             </box>
           </geometry>
        </visual>
        <collision name="eslabon2C">
           <pose>0 0 0 0 0 0</pose>
           <geometry>
	     <box>
               <size>0.05 0.05 1</size>
             </box>
           </geometry>
           <surface>
	     <contact>
	       <ode>
	          <soft_cfm>0</soft_cfm>
	          <soft_erp>0.2</soft_erp>
	          <kp>1e+13</kp>
	          <kd>1e+11</kd>
	          <max_vel>-1</max_vel>
	          <max_depth>0</max_depth>
	        </ode>
	     </contact>
            <friction>
              <torcional>
	        <ode>
	        </ode>
              </torcional>
            </friction>
          </surface>
      </collision>
     </link>



     <joint name="eslabon1J" type="revolute">
        <pose frame="">0 0 -0.5 0 0 0</pose>
        <parent>base</parent>
        <child>eslabon1</child>
        <axis>
	  <dynamics>
	     <damping>1</damping>
	     <friction>0</friction>
	     <spring_reference>0</spring_reference>>
	     <spring_stiffness>0</spring_stiffness>
	  </dynamics>
	  <limit>
	    <lower>-3.14</lower>
	    <upper>3.14</upper>
	<effort>0</effort>
	    <velocity>0</velocity> 
	  </limit>
	  <xyz>0 0 1</xyz>
	  <use_parent_model_frame>1</use_parent_model_frame>
	</axis>
     </joint>

     <joint name="eslabon2J" type="revolute">
        <pose frame="">0 0 -0.475 0 0 0</pose>
        <parent>eslabon1</parent>
        <child>eslabon2</child>
        <axis>
	  <dynamics>
	     <damping>1</damping>
	     <friction>0</friction>
	     <spring_reference>0</spring_reference>>
	     <spring_stiffness>0</spring_stiffness>
	  </dynamics>
	  <limit>
	    <lower>0</lower>
	    <upper>3.14</upper>
	  </limit>
	  <xyz>1 0 0</xyz>
	  <use_parent_model_frame>1</use_parent_model_frame>
	</axis>
     </joint> 

  </model>
 </world>
</sdf>
