<?xml version="1.0"?>

<robot name="planar_3dof" xmlns:xacro="http://www.ros.org/wiki/xacro">


  <xacro:macro name="base_link_geometry" >
    <mesh filename="package://lesson_urdf/meshes/arm_link.stl"/>
  </xacro:macro>
  
  <xacro:macro name="gripper_link_geometry" >
    <mesh filename="package://lesson_urdf/meshes/gripper.stl"/>
  </xacro:macro>
  
<link name="world"/>

<link name="base_link">
<visual>
  <geometry>
   <cylinder length="0.1" radius="0.2"/>
  </geometry>
   <origin rpy="0 0 0" xyz="0 0 0"/>
</visual>
</link>

<joint name="fixed" type="fixed">
    <parent link="world"/>
    <child link="base_link"/>
</joint>

<link name="link_1">
<visual>
  <geometry>
    <xacro:base_link_geometry/>
  </geometry>
<material name="grey">
  <color rgba="0.7 0.7 0.7 1.0"/>
</material>
</visual> 
<collision>
    <geometry>
        <cylinder length="0.5" radius="0.05"/>
    </geometry>
    <origin rpy="0 1.5708 0" xyz="0.25 0 0"/>
</collision>
    <inertial>
      <origin xyz="0 0 .25" rpy="0 0 0"/>
      <mass value="1"/>
      <inertia
        ixx="1.0" ixy="0.0" ixz="0.0"
        iyy="1.0" iyz="0.0"
        izz="1.0"/>
    </inertial>
</link>
<joint name="joint_1" type="revolute">
<parent link="base_link"/>
<child link="link_1"/>
<origin xyz="0 0 0.05" rpy="0 0 0"/>
<axis xyz="0 0 1"/>
<limit lower="-1.57" upper="1.57" effort="0" velocity="0.5"/>
</joint>

<link name="link_2">
<visual>
  <geometry>
    <xacro:base_link_geometry/>
  </geometry>

</visual>
<collision>
  <geometry>
    <xacro:base_link_geometry/>
  </geometry>
</collision> 
    <inertial>
      <origin xyz="0 0 0.25" rpy="0 0 0"/>
      <mass value="1"/>
      <inertia
        ixx="1.0" ixy="0.0" ixz="0.0"
        iyy="1.0" iyz="0.0"
        izz="1.0"/>
    </inertial>
</link>

<joint name="joint_2" type="revolute">
<parent link="link_1"/>
<child link="link_2"/>
<origin xyz="0.5 0.0 0.0" rpy="0.0 0 0.0" />
<axis xyz="0 0 1"/>
<limit lower="-1.57" upper="1.57" effort="0" velocity="0.5"/>
</joint>

<link name="gripper">
<visual>
  <geometry>
    <xacro:gripper_link_geometry/>
  </geometry>

</visual>
<collision>
  <geometry>
    <xacro:gripper_link_geometry/>
  </geometry>
</collision> 
    <inertial>
      <origin xyz="0 0 0.1" rpy="0 0 0"/>
      <mass value="1"/>
      <inertia
        ixx="1.0" ixy="0.0" ixz="0.0"
        iyy="1.0" iyz="0.0"
        izz="1.0"/>
    </inertial>
</link>

<joint name="joint_3" type="revolute">
<parent link="link_2"/>
<child link="gripper"/>
<origin xyz="0.5 0.0 0.0" rpy="0.0 0 0.0" />
<axis xyz="0 0 1"/>
<limit lower="-1.57" upper="1.57" effort="0" velocity="0.5"/>
</joint>
<link name="end" />

<joint name="gripper_end" type="fixed" >
    <parent link="gripper" />
    <child link="end" />
    <origin xyz="0.18 0 0" rpy="0 0 0" />
 </joint>

</robot>
