<?xml version="1.0"?>
<robot name="My_Robot">


    <material name="red">
        <color rgba="0.8 0.0 0.0 1.0"/>
    </material>

    <material name="cyan">
        <color rgba="0 1.0 1.0 1.0"/>
    </material>

    <material name="grey">
        <color rgba="0.4 0.4 0.4 1.0"/>
    </material>


	<link name="world" />

        <link name="base_link">
        <visual>
            <origin xyz="1.3 -1.1 2.85" rpy="0 0.0 0.0"/>
            <geometry>
                <mesh filename="package://lesson_urdf/meshes/visual/STL_Link_Base.stl" scale="0.1 0.1 0.1"/>
            </geometry>
            <material name="grey"/>
        </visual>
        </link>

        <joint name="Join" type="fixed">
            <parent link="world"/>
            <child link="base_link"/>
        </joint>

	<link name="link_1">
            <visual>
                <origin xyz="2.2 -0.1 2.2" rpy="0.0 0.0 6"/>
                <geometry>
                    <mesh filename="package://lesson_urdf/meshes/visual/STL_Link_1.stl" scale="0.1 0.1 0.1"/>
                </geometry>
                <material name="cyan"/>
            </visual>
        </link>

        <joint name="joint_1" type="revolute">
            <origin xyz="0.0 0.0 6" rpy="0.0 0.0 0.0"/>
            <parent link="base_link"/>
            <child link="link_1"/>
            <axis xyz="0.0 0.0 1.0"/>
            <limit lower="-3.14" upper="3.14" effort="5.0" velocity="5.0"/>
        </joint>
        
        <link name="link_2">
            <visual>
                <origin xyz="1.2 3.3 4.1" rpy="0.0 0.0 6.0"/>
                <geometry>
                    <mesh filename="package://lesson_urdf/meshes/visual/STL_Link_2.stl" scale="0.1 0.1 0.1"/>
                </geometry>
                <material name="red"/>
            </visual>
        </link>

        <joint name="joint_2" type="revolute">
            <origin xyz="0.0 1.0 3.1" rpy="0.8 0.0 0.0"/>
            <parent link="link_1"/>
            <child link="link_2"/>
            <axis xyz="1.0 0.0 0.0"/>
            <limit lower="-1.9" upper="1.7" effort="5.0" velocity="5.0"/>
        </joint>
 
         <link name="link_3">
            <visual>
                <origin xyz="3.8 5.5 1.9" rpy="0.0 0.0 -0.3"/>
                <geometry>
                    <mesh filename="package://lesson_urdf/meshes/visual/STL_Link_3.stl" scale="0.1 0.1 0.1"/>
                </geometry>
                <material name="cyan"/>
            </visual>
        </link>

        <joint name="joint_3" type="revolute">
            <origin xyz="0.0 8.8 8.5" rpy="0.45 0.0 0.0"/>
            <parent link="link_2"/>
            <child link="link_3"/>
            <axis xyz="1.0 0.0 0.0"/>
            <limit lower="-2.6" upper="2.6" effort="5.0" velocity="5.0"/>
        </joint>
        
        <link name="link_4">
            <visual>
                <origin xyz="1.6 3.7 0.3" rpy="0.0 0.0 -0.3"/>
                <geometry>
                    <mesh filename="package://lesson_urdf/meshes/visual/STL_Link_4.stl" scale="0.1 0.1 0.1"/>
                </geometry>
                <material name="red"/>
            </visual>
        </link>

        <joint name="joint_4" type="revolute">
            <origin xyz="0.0 11.6 4.3" rpy="0.4 0.0 0.0"/>
            <parent link="link_3"/>
            <child link="link_4"/>
            <axis xyz="1.0 0.0 0.0"/>
            <limit lower="-2.5" upper="2.2" effort="5.0" velocity="5.0"/>
        </joint>
 
         <link name="Gripper">
            <visual>
                <origin xyz="0.6 5.8 0.6" rpy="0.0 0.0 -0.3"/>
                <geometry>
                    <mesh filename="package://lesson_urdf/meshes/visual/STL_Link_5.stl" scale="0.1 0.1 0.1"/>
                </geometry>
                <material name="grey"/>
            </visual>
        </link>

        <joint name="joint_Gripper" type="revolute">
            <origin xyz="1.0 7.1 1.1" rpy="0.0 0.0 0.0"/>
            <parent link="link_4"/>
            <child link="Gripper"/>
            <axis xyz="0.0 1.0 0.0"/>
            <limit lower="-3.14" upper="3.14" effort="5.0" velocity="5.0"/>
        </joint>
        
                
        <link name="end" />

  	<joint name="gripper_end" type="fixed">
    	    <parent link="Gripper" />
    	    <child link="end" />
    	    <origin xyz="0.3 10.0 0.0" rpy="0 0 0" />
    	</joint>

</robot>
